Workbook

Sheet Medical_Examinations
A1: Customer ID | B1: BMI | C1: Weight Status | D1: HBA1C | E1: Diabetes Status | F1: Heart Issues | G1: Any Transplants | H1: Cancer history | I1: NumberOfMajorSurgeries | J1: NumberOfMajorSurgeries 2 | K1: smoker | L1: Column9 | M1: Column10 | N1: Column11 | O1: Column12 | P1: Column13 | Q1: Column14
A2: Id1 | B2: 47.41 | C2: {=_xlfn.IFS(B2<=18.5, "Underweight",B2<=24.9,"Normal weight",B2<=29.9, "Over weight",B2>=30,"Obesity")} -> Obesity | D2: 7.47 | E2: {=_xlfn.IFS(D2<5.7,"Normal",D2<=6.4,"Prediabetes",D2>=6.5,"Diabetes")} -> Diabetes | F2: No | G2: No | H2: No | I2: No major surgery | J2: 0 | K2: Yes | O2: 1 | P2: Customer ID | Q2: 0
A3: Id2 | B3: 30.36 | C3: {=_xlfn.IFS(B3<=18.5, "Underweight",B3<=24.9,"Normal weight",B3<=29.9, "Over weight",B3>=30,"Obesity")} -> Obesity | D3: 5.77 | E3: {=_xlfn.IFS(D3<5.7,"Normal",D3<=6.4,"Prediabetes",D3>=6.5,"Diabetes")} -> Prediabetes | F3: No | G3: No | H3: No | I3: No major surgery | J3: 0 | K3: Yes | P3: BMI | Q3: 0
A4: Id3 | B4: 34.485 | C4: {=_xlfn.IFS(B4<=18.5, "Underweight",B4<=24.9,"Normal weight",B4<=29.9, "Over weight",B4>=30,"Obesity")} -> Obesity | D4: 11.87 | E4: {=_xlfn.IFS(D4<5.7,"Normal",D4<=6.4,"Prediabetes",D4>=6.5,"Diabetes")} -> Diabetes | F4: Yes | G4: No | H4: No | I4: 2 | J4: 2 | K4: Yes | P4: HBA1C | Q4: 0
A5: Id4 | B5: 38.095 | C5: {=_xlfn.IFS(B5<=18.5, "Underweight",B5<=24.9,"Normal weight",B5<=29.9, "Over weight",B5>=30,"Obesity")} -> Obesity | D5: 6.05 | E5: {=_xlfn.IFS(D5<5.7,"Normal",D5<=6.4,"Prediabetes",D5>=6.5,"Diabetes")} -> Prediabetes | F5: No | G5: No | H5: No | I5: No major surgery | J5: 0 | K5: Yes | P5: Heart Issues | Q5: 0
A6: Id5 | B6: 35.53 | C6: {=_xlfn.IFS(B6<=18.5, "Underweight",B6<=24.9,"Normal weight",B6<=29.9, "Over weight",B6>=30,"Obesity")} -> Obesity | D6: 5.45 | E6: {=_xlfn.IFS(D6<5.7,"Normal",D6<=6.4,"Prediabetes",D6>=6.5,"Diabetes")} -> Normal | F6: No | G6: No | H6: No | I6: No major surgery | J6: 0 | K6: Yes | P6: Any transplants | Q6: 0
A7: Id6 | B7: 32.8 | C7: {=_xlfn.IFS(B7<=18.5, "Underweight",B7<=24.9,"Normal weight",B7<=29.9, "Over weight",B7>=30,"Obesity")} -> Obesity | D7: 6.59 | E7: {=_xlfn.IFS(D7<5.7,"Normal",D7<=6.4,"Prediabetes",D7>=6.5,"Diabetes")} -> Diabetes | F7: No | G7: No | H7: No | I7: No major surgery | J7: 0 | K7: Yes | P7: Cancer history | Q7: 0
A8: Id7 | B8: 36.4 | C8: {=_xlfn.IFS(B8<=18.5, "Underweight",B8<=24.9,"Normal weight",B8<=29.9, "Over weight",B8>=30,"Obesity")} -> Obesity | D8: 6.07 | E8: {=_xlfn.IFS(D8<5.7,"Normal",D8<=6.4,"Prediabetes",D8>=6.5,"Diabetes")} -> Prediabetes | F8: No | G8: No | H8: No | I8: No major surgery | J8: 0 | K8: Yes | P8: No.of surgeries | Q8: 0
A9: Id8 | B9: 36.96 | C9: {=_xlfn.IFS(B9<=18.5, "Underweight",B9<=24.9,"Normal weight",B9<=29.9, "Over weight",B9>=30,"Obesity")} -> Obesity | D9: 7.93 | E9: {=_xlfn.IFS(D9<5.7,"Normal",D9<=6.4,"Prediabetes",D9>=6.5,"Diabetes")} -> Diabetes | F9: No | G9: No | H9: No | I9: 3 | J9: 3 | K9: Yes | P9: Smoker | Q9: 2
A10: Id9 | B10: 41.14 | C10: {=_xlfn.IFS(B10<=18.5, "Underweight",B10<=24.9,"Normal weight",B10<=29.9, "Over weight",B10>=30,"Obesity")} -> Obesity | D10: 9.58 | E10: {=_xlfn.IFS(D10<5.7,"Normal",D10<=6.4,"Prediabetes",D10>=6.5,"Diabetes")} -> Diabetes | F10: Yes | G10: No | H10: Yes | I10: 1 | J10: 1 | K10: Yes
A11: Id10 | B11: 38.06 | C11: {=_xlfn.IFS(B11<=18.5, "Underweight",B11<=24.9,"Normal weight",B11<=29.9, "Over weight",B11>=30,"Obesity")} -> Obesity | D11: 10.79 | E11: {=_xlfn.IFS(D11<5.7,"Normal",D11<=6.4,"Prediabetes",D11>=6.5,"Diabetes")} -> Diabetes | F11: No | G11: No | H11: No | I11: No major surgery | J11: 0 | K11: Yes
A12: Id11 | B12: 37.7 | C12: {=_xlfn.IFS(B12<=18.5, "Underweight",B12<=24.9,"Normal weight",B12<=29.9, "Over weight",B12>=30,"Obesity")} -> Obesity | D12: 5.96 | E12: {=_xlfn.IFS(D12<5.7,"Normal",D12<=6.4,"Prediabetes",D12>=6.5,"Diabetes")} -> Prediabetes | F12: Yes | G12: No | H12: No | I12: 2 | J12: 2 | K12: Yes
A13: Id12 | B13: 42.13 | C13: {=_xlfn.IFS(B13<=18.5, "Underweight",B13<=24.9,"Normal weight",B13<=29.9, "Over weight",B13>=30,"Obesity")} -> Obesity | D13: 11.9 | E13: {=_xlfn.IFS(D13<5.7,"Normal",D13<=6.4,"Prediabetes",D13>=6.5,"Diabetes")} -> Diabetes | F13: No | G13: No | H13: No | I13: No major surgery | J13: 0 | K13: Yes
A14: Id13 | B14: 40.92 | C14: {=_xlfn.IFS(B14<=18.5, "Underweight",B14<=24.9,"Normal weight",B14<=29.9, "Over weight",B14>=30,"Obesity")} -> Obesity | D14: 8.41 | E14: {=_xlfn.IFS(D14<5.7,"Normal",D14<=6.4,"Prediabetes",D14>=6.5,"Diabetes")} -> Diabetes | F14: No | G14: No | H14: No | I14: No major surgery | J14: 0 | K14: Yes
A15: Id14 | B15: 40.565 | C15: {=_xlfn.IFS(B15<=18.5, "Underweight",B15<=24.9,"Normal weight",B15<=29.9, "Over weight",B15>=30,"Obesity")} -> Obesity | D15: 7.02 | E15: {=_xlfn.IFS(D15<5.7,"Normal",D15<=6.4,"Prediabetes",D15>=6.5,"Diabetes")} -> Diabetes | F15: No | G15: No | H15: No | I15: No major surgery | J15: 0 | K15: Yes
A16: Id15 | B16: 36.385 | C16: {=_xlfn.IFS(B16<=18.5, "Underweight",B16<=24.9,"Normal weight",B16<=29.9, "Over weight",B16>=30,"Obesity")} -> Obesity | D16: 7.59 | E16: {=_xlfn.IFS(D16<5.7,"Normal",D16<=6.4,"Prediabetes",D16>=6.5,"Diabetes")} -> Diabetes | F16: Yes | G16: No | H16: No | I16: 2 | J16: 2 | K16: Yes
A17: Id16 | B17: 39.9 | C17: {=_xlfn.IFS(B17<=18.5, "Underweight",B17<=24.9,"Normal weight",B17<=29.9, "Over weight",B17>=30,"Obesity")} -> Obesity | D17: 11.32 | E17: {=_xlfn.IFS(D17<5.7,"Normal",D17<=6.4,"Prediabetes",D17>=6.5,"Diabetes")} -> Diabetes | F17: No | G17: No | H17: No | I17: No major surgery | J17: 0 | K17: Yes
A18: Id17 | B18: 33.8 | C18: {=_xlfn.IFS(B18<=18.5, "Underweight",B18<=24.9,"Normal weight",B18<=29.9, "Over weight",B18>=30,"Obesity")} -> Obesity | D18: 7.67 | E18: {=_xlfn.IFS(D18<5.7,"Normal",D18<=6.4,"Prediabetes",D18>=6.5,"Diabetes")} -> Diabetes | F18: No | G18: No | H18: No | I18: 3 | J18: 3 | K18: Yes
A19: Id18 | B19: 36.765 | C19: {=_xlfn.IFS(B19<=18.5, "Underweight",B19<=24.9,"Normal weight",B19<=29.9, "Over weight",B19>=30,"Obesity")} -> Obesity | D19: 7.29 | E19: {=_xlfn.IFS(D19<5.7,"Normal",D19<=6.4,"Prediabetes",D19>=6.5,"Diabetes")} -> Diabetes | F19: Yes | G19: No | H19: Yes | I19: 1 | J19: 1 | K19: Yes
A20: Id19 | B20: 36.955 | C20: {=_xlfn.IFS(B20<=18.5, "Underweight",B20<=24.9,"Normal weight",B20<=29.9, "Over weight",B20>=30,"Obesity")} -> Obesity | D20: 4.72 | E20: {=_xlfn.IFS(D20<5.7,"Normal",D20<=6.4,"Prediabetes",D20>=6.5,"Diabetes")} -> Normal | F20: Yes | G20: No | H20: No | I20: 1 | J20: 1 | K20: Yes
A21: Id20 | B21: 42.9 | C21: {=_xlfn.IFS(B21<=18.5, "Underweight",B21<=24.9,"Normal weight",B21<=29.9, "Over weight",B21>=30,"Obesity")} -> Obesity | D21: 11.41 | E21: {=_xlfn.IFS(D21<5.7,"Normal",D21<=6.4,"Prediabetes",D21>=6.5,"Diabetes")} -> Diabetes | F21: No | G21: No | H21: No | I21: No major surgery | J21: 0 | K21: Yes
A22: Id21 | B22: 36.3 | C22: {=_xlfn.IFS(B22<=18.5, "Underweight",B22<=24.9,"Normal weight",B22<=29.9, "Over weight",B22>=30,"Obesity")} -> Obesity | D22: 11.5 | E22: {=_xlfn.IFS(D22<5.7,"Normal",D22<=6.4,"Prediabetes",D22>=6.5,"Diabetes")} -> Diabetes | F22: Yes | G22: No | H22: No | I22: 2 | J22: 2 | K22: Yes
A23: Id22 | B23: 32.2 | C23: {=_xlfn.IFS(B23<=18.5, "Underweight",B23<=24.9,"Normal weight",B23<=29.9, "Over weight",B23>=30,"Obesity")} -> Obesity | D23: 6.22 | E23: {=_xlfn.IFS(D23<5.7,"Normal",D23<=6.4,"Prediabetes",D23>=6.5,"Diabetes")} -> Prediabetes | F23: Yes | G23: No | H23: No | I23: 2 | J23: 2 | K23: Yes
A24: Id23 | B24: 31.3 | C24: {=_xlfn.IFS(B24<=18.5, "Underweight",B24<=24.9,"Normal weight",B24<=29.9, "Over weight",B24>=30,"Obesity")} -> Obesity | D24: 11.38 | E24: {=_xlfn.IFS(D24<5.7,"Normal",D24<=6.4,"Prediabetes",D24>=6.5,"Diabetes")} -> Diabetes | F24: No | G24: No | H24: No | I24: 3 | J24: 3 | K24: Yes
A25: Id24 | B25: 41.8 | C25: {=_xlfn.IFS(B25<=18.5, "Underweight",B25<=24.9,"Normal weight",B25<=29.9, "Over weight",B25>=30,"Obesity")} -> Obesity | D25: 7.89 | E25: {=_xlfn.IFS(D25<5.7,"Normal",D25<=6.4,"Prediabetes",D25>=6.5,"Diabetes")} -> Diabetes | F25: Yes | G25: No | H25: No | I25: 2 | J25: 2 | K25: Yes
A26: Id25 | B26: 35.09 | C26: {=_xlfn.IFS(B26<=18.5, "Underweight",B26<=24.9,"Normal weight",B26<=29.9, "Over weight",B26>=30,"Obesity")} -> Obesity | D26: 4.38 | E26: {=_xlfn.IFS(D26<5.7,"Normal",D26<=6.4,"Prediabetes",D26>=6.5,"Diabetes")} -> Normal | F26: Yes | G26: No | H26: No | I26: 2 | J26: 2 | K26: Yes
A27: Id26 | B27: 33.88 | C27: {=_xlfn.IFS(B27<=18.5, "Underweight",B27<=24.9,"Normal weight",B27<=29.9, "Over weight",B27>=30,"Obesity")} -> Obesity | D27: 7.01 | E27: {=_xlfn.IFS(D27<5.7,"Normal",D27<=6.4,"Prediabetes",D27>=6.5,"Diabetes")} -> Diabetes | F27: No | G27: No | H27: No | I27: 3 | J27: 3 | K27: Yes
A28: Id27 | B28: 30.875 | C28: {=_xlfn.IFS(B28<=18.5, "Underweight",B28<=24.9,"Normal weight",B28<=29.9, "Over weight",B28>=30,"Obesity")} -> Obesity | D28: 11.88 | E28: {=_xlfn.IFS(D28<5.7,"Normal",D28<=6.4,"Prediabetes",D28>=6.5,"Diabetes")} -> Diabetes | F28: No | G28: No | H28: No | I28: No major surgery | J28: 0 | K28: Yes
A29: Id28 | B29: 36.86 | C29: {=_xlfn.IFS(B29<=18.5, "Underweight",B29<=24.9,"Normal weight",B29<=29.9, "Over weight",B29>=30,"Obesity")} -> Obesity | D29: 5.19 | E29: {=_xlfn.IFS(D29<5.7,"Normal",D29<=6.4,"Prediabetes",D29>=6.5,"Diabetes")} -> Normal | F29: Yes | G29: No | H29: Yes | I29: 1 | J29: 1 | K29: Yes
A30: Id29 | B30: 35.86 | C30: {=_xlfn.IFS(B30<=18.5, "Underweight",B30<=24.9,"Normal weight",B30<=29.9, "Over weight",B30>=30,"Obesity")} -> Obesity | D30: 6.74 | E30: {=_xlfn.IFS(D30<5.7,"Normal",D30<=6.4,"Prediabetes",D30>=6.5,"Diabetes")} -> Diabetes | F30: Yes | G30: No | H30: No | I30: 2 | J30: 2 | K30: Yes
A31: Id30 | B31: 37.05 | C31: {=_xlfn.IFS(B31<=18.5, "Underweight",B31<=24.9,"Normal weight",B31<=29.9, "Over weight",B31>=30,"Obesity")} -> Obesity | D31: 8.44 | E31: {=_xlfn.IFS(D31<5.7,"Normal",D31<=6.4,"Prediabetes",D31>=6.5,"Diabetes")} -> Diabetes | F31: No | G31: No | H31: No | I31: No major surgery | J31: 0 | K31: Yes
A32: Id31 | B32: 43.89 | C32: {=_xlfn.IFS(B32<=18.5, "Underweight",B32<=24.9,"Normal weight",B32<=29.9, "Over weight",B32>=30,"Obesity")} -> Obesity | D32: 8.71 | E32: {=_xlfn.IFS(D32<5.7,"Normal",D32<=6.4,"Prediabetes",D32>=6.5,"Diabetes")} -> Diabetes | F32: No | G32: No | H32: No | I32: No major surgery | J32: 0 | K32: Yes
A33: Id32 | B33: 42.35 | C33: {=_xlfn.IFS(B33<=18.5, "Underweight",B33<=24.9,"Normal weight",B33<=29.9, "Over weight",B33>=30,"Obesity")} -> Obesity | D33: 5.08 | E33: {=_xlfn.IFS(D33<5.7,"Normal",D33<=6.4,"Prediabetes",D33>=6.5,"Diabetes")} -> Normal | F33: Yes | G33: No | H33: No | I33: No major surgery | J33: 0 | K33: Yes
A34: Id33 | B34: 31.35 | C34: {=_xlfn.IFS(B34<=18.5, "Underweight",B34<=24.9,"Normal weight",B34<=29.9, "Over weight",B34>=30,"Obesity")} -> Obesity | D34: 6.86 | E34: {=_xlfn.IFS(D34<5.7,"Normal",D34<=6.4,"Prediabetes",D34>=6.5,"Diabetes")} -> Diabetes | F34: No | G34: No | H34: No | I34: No major surgery | J34: 0 | K34: Yes
A35: Id34 | B35: 47.6 | C35: {=_xlfn.IFS(B35<=18.5, "Underweight",B35<=24.9,"Normal weight",B35<=29.9, "Over weight",B35>=30,"Obesity")} -> Obesity | D35: 5.95 | E35: {=_xlfn.IFS(D35<5.7,"Normal",D35<=6.4,"Prediabetes",D35>=6.5,"Diabetes")} -> Prediabetes | F35: Yes | G35: No | H35: No | I35: No major surgery | J35: 0 | K35: Yes
A36: Id35 | B36: 46.2 | C36: {=_xlfn.IFS(B36<=18.5, "Underweight",B36<=24.9,"Normal weight",B36<=29.9, "Over weight",B36>=30,"Obesity")} -> Obesity | D36: 6.09 | E36: {=_xlfn.IFS(D36<5.7,"Normal",D36<=6.4,"Prediabetes",D36>=6.5,"Diabetes")} -> Prediabetes | F36: No | G36: No | H36: Yes | I36: 1 | J36: 1 | K36: Yes
A37: Id36 | B37: 32.015 | C37: {=_xlfn.IFS(B37<=18.5, "Underweight",B37<=24.9,"Normal weight",B37<=29.9, "Over weight",B37>=30,"Obesity")} -> Obesity | D37: 11.75 | E37: {=_xlfn.IFS(D37<5.7,"Normal",D37<=6.4,"Prediabetes",D37>=6.5,"Diabetes")} -> Diabetes | F37: No | G37: No | H37: No | I37: No major surgery | J37: 0 | K37: Yes
A38: Id37 | B38: 40.565 | C38: {=_xlfn.IFS(B38<=18.5, "Underweight",B38<=24.9,"Normal weight",B38<=29.9, "Over weight",B38>=30,"Obesity")} -> Obesity | D38: 7.37 | E38: {=_xlfn.IFS(D38<5.7,"Normal",D38<=6.4,"Prediabetes",D38>=6.5,"Diabetes")} -> Diabetes | F38: No | G38: No | H38: No | I38: No major surgery | J38: 0 | K38: Yes
A39: Id38 | B39: 32.45 | C39: {=_xlfn.IFS(B39<=18.5, "Underweight",B39<=24.9,"Normal weight",B39<=29.9, "Over weight",B39>=30,"Obesity")} -> Obesity | D39: 11.91 | E39: {=_xlfn.IFS(D39<5.7,"Normal",D39<=6.4,"Prediabetes",D39>=6.5,"Diabetes")} -> Diabetes | F39: No | G39: No | H39: No | I39: No major surgery | J39: 0 | K39: Yes
A40: Id39 | B40: 34.96 | C40: {=_xlfn.IFS(B40<=18.5, "Underweight",B40<=24.9,"Normal weight",B40<=29.9, "Over weight",B40>=30,"Obesity")} -> Obesity | D40: 6.52 | E40: {=_xlfn.IFS(D40<5.7,"Normal",D40<=6.4,"Prediabetes",D40>=6.5,"Diabetes")} -> Diabetes | F40: No | G40: No | H40: No | I40: No major surgery | J40: 0 | K40: Yes
...

Sheet Customer_Names
A1: Customer ID | B1: name | C1: Title | D1: First Name | E1: Last Name
A2: Id1 | B2: Hawks, Ms. Kelly | C2: Ms. | D2: Kelly | E2: Hawks
A3: Id2 | B3: Lehner, Mr. Matthew D | C3: Mr. | D3: Matthew D | E3: Lehner
A4: Id3 | B4: Lu, Mr. Phil | C4: Mr. | D4: Phil | E4: Lu
A5: Id4 | B5: Osborne, Ms. Kelsey | C5: Ms. | D5: Kelsey | E5: Osborne
A6: Id5 | B6: Kadala, Ms. Kristyn | C6: Ms. | D6: Kristyn | E6: Kadala
A7: Id6 | B7: Baker, Mr. Russell B. | C7: Mr. | D7: Russell B. | E7: Baker
A8: Id7 | B8: Macpherson, Mr. Scott | C8: Mr. | D8: Scott | E8: Macpherson
A9: Id8 | B9: Hallman, Mr. Stephen | C9: Mr. | D9: Stephen | E9: Hallman
A10: Id9 | B10: Moran, Mr. Patrick R. | C10: Mr. | D10: Patrick R. | E10: Moran
A11: Id10 | B11: Benner, Ms. Brooke N. | C11: Ms. | D11: Brooke N. | E11: Benner
A12: Id11 | B12: Fierro Vargas, Ms. Paola Andrea | C12: Ms. | D12: Ms. Paola Andrea | E12: Fierro Vargas
... A2336: Id2335 | B2336: German, Mr. Aaron K | C2336: Mr. | D2336: Aaron K | E2336: German

Sheet Hospitalisation_Details_2__2
A1: Customer ID | B1: year | C1: Year 2 | D1: month | E1: Month 2 | F1: date | G1: Date of Birth | H1: children | I1: $charges | J1: Hospital tier | K1: City tier | L1: State ID | M1: Age | N1: Column15 | O1: Column16 | P1: Column2
A2: Id2335 | B2: 1992 | C2: 1992 | D2: Jul | E2: Jul | F2: 9 | G2: 33794 | H2: 0 | I2: $563.84 | J2: tier - 2 | K2: tier - 3 | L2: R1013 | M2: 34 | N2: Customer id | O2: 6
A3: Id2334 | B3: 1992 | C3: 1992 | D3: Nov | E3: Nov | F3: 30 | G3: 33938 | H3: 0 | I3: $570.62 | J3: tier - 2 | K3: tier - 1 | L3: R1013 | M3: 34 | N3: Year | O3: 2
A4: Id2333 | B4: 1993 | C4: 1993 | D4: Jun | E4: Jun | F4: 30 | G4: 34150 | H4: 0 | I4: $600 | J4: tier - 2 | K4: tier - 1 | L4: R1013 | M4: 33 | N4: Month | O4: 3
A5: Id2332 | B5: 1992 | C5: 1992 | D5: Sep | E5: Sep | F5: 13 | G5: 33860 | H5: 0 | I5: $604.54 | J5: tier - 3 | K5: tier - 3 | L5: R1013 | M5: 34 | N5: Date | O5: 0
A6: Id2331 | B6: 1998 | C6: 1998 | D6: Jul | E6: Jul | F6: 27 | G6: 36003 | H6: 0 | I6: $637.26 | J6: tier - 3 | K6: tier - 3 | L6: R1013 | M6: 28 | N6: Children | O6: 0
A7: Id2330 | B7: 2001 | C7: 2001 | D7: Nov | E7: Nov | F7: 20 | G7: 37215 | H7: 0 | I7: $646.14 | J7: tier - 3 | K7: tier - 3 | L7: R1012 | M7: 25 | N7: Charges | O7: 0
A8: Id2329 | B8: 1993 | C8: 1993 | D8: Jun | E8: Jun | F8: 1 | G8: 34121 | H8: 0 | I8: $650 | J8: tier - 3 | K8: tier - 3 | L8: R1013 | M8: 33 | N8: Hosp tier | O8: 1
A9: Id2328 | B9: 1995 | C9: 1995 | D9: Jul | E9: Jul | F9: 4 | G9: 34884 | H9: 0 | I9: $650 | J9: tier - 3 | K9: tier - 3 | L9: R1013 | M9: 31 | N9: City tier | O9: 1
A10: Id2327 | B10: 2002 | C10: 2002 | D10: Nov | E10: Nov | F10: 29 | G10: 37589 | H10: 0 | I10: $668 | J10: tier - 3 | K10: tier - 2 | L10: R1012 | M10: 24 | N10: State id | O10: 2
A11: Id2326 | B11: 1997 | C11: 1997 | D11: Nov | E11: Nov | F11: 9 | G11: 35743 | H11: 0 | I11: $670 | J11: tier - 3 | K11: tier - 3 | L11: R1013 | M11: 29
A12: Id2325 | B12: 2001 | C12: 2001 | D12: Sep | E12: Sep | F12: 12 | G12: 37146 | H12: 0 | I12: $687.54 | J12: tier - 3 | K12: tier - 2 | L12: R1013 | M12: 25
A13: Id2324 | B13: 1999 | C13: 1999 | D13: Dec | E13: Dec | F13: 26 | G13: 36520 | H13: 0 | I13: $700 | J13: tier-2 | K13: tier - 3 | L13: R1013 | M13: 27
A14: Id2323 | B14: 1999 | C14: 1999 | D14: Dec | E14: Dec | F14: 14 | G14: 36508 | H14: 0 | I14: $722.99 | J14: tier - 3 | K14: tier - 1 | L14: R1013 | M14: 27
A15: Id2322 | B15: 2002 | C15: 2002 | D15: ? | E15: Sep | F15: 19 | G15: 37518 | H15: 0 | I15: $750 | J15: tier - 3 | K15: tier - 1 | L15: R1012 | M15: 24
A16: Id2321 | B16: 1993 | C16: 1993 | D16: Aug | E16: Aug | F16: 9 | G16: 34190 | H16: 0 | I16: $760 | J16: tier - 3 | K16: tier - 1 | L16: R1013 | M16: 33
A17: Id2320 | B17: 1996 | C17: 1996 | D17: Oct | E17: Oct | F17: 22 | G17: 35360 | H17: 0 | I17: $760 | J17: tier - 3 | K17: tier - 3 | L17: R1013 | M17: 30
A18: Id2319 | B18: 1993 | C18: 1993 | D18: Jun | E18: Jun | F18: 28 | G18: 34148 | H18: 0 | I18: $770 | J18: tier - 3 | K18: tier - 3 | L18: R1013 | M18: 33
A19: Id2318 | B19: 1996 | C19: 1996 | D19: ? | E19: Sep | F19: 18 | G19: 35326 | H19: 0 | I19: $770.38 | J19: tier - 3 | K19: tier-2 | L19: R1012 | M19: 30
A20: Id2317 | B20: 1995 | C20: 1995 | D20: Dec | E20: Dec | F20: 7 | G20: 35040 | H20: 0 | I20: $773.54 | J20: tier - 3 | K20: tier - 2 | L20: R1013 | M20: 31
A21: Id2316 | B21: 2004 | C21: 2004 | D21: Oct | E21: Oct | F21: 7 | G21: 38267 | H21: 0 | I21: $830.52 | J21: tier - 3 | K21: tier - 2 | L21: R1011 | M21: 22
A22: Id2315 | B22: 2000 | C22: 2000 | D22: Nov | E22: Nov | F22: 18 | G22: 36848 | H22: 0 | I22: $865.41 | J22: tier - 3 | K22: tier - 1 | L22: R1013 | M22: 26
... A1050: Id1290 | B1050: 1977 | C1050: 1977 | D1050: Jul | E1050: Jul | F1050: 26 | G1050: 28332 | H1050: 2 | I1050: $8527.5300000000007 | J1050: tier - 2 | K1050: tier - 2 | L1050: R1013 | M1050: 49
A1051: Id1289 | C1051: 1983 | D1051: Jul | E1051: Jul | F1051: 24 | H1051: 0 | I1051: $8534.67 | J1051: tier - 2 | K1051: tier - 3 | L1051: R1024
A1052: Id1288 | B1052: 1981 | C1052: 1981 | D1052: Dec | E1052: Dec | F1052: 27 | G1052: 29947 | H1052: 3 | I1052: $8538.2900000000009 | J1052: tier - 2 | K1052: tier - 3 | L1052: R1024 | M1052: 45
A1053: Id1287 | B1053: 1975 | C1053: 1975 | D1053: Nov | E1053: Nov | F1053: 6 | G1053: 27704 | H1053: 1 | I1053: $8539.67 | J1053: tier - 2 | K1053: tier - 3 | L1053: R1011 | M1053: 51
A1054: Id1286 | C1054: 1983 | D1054: Dec | E1054: Dec | F1054: 12 | H1054: 1 | I1054: $8547.69 | J1054: tier - 2 | K1054: tier - 1 | L1054: R1013
A1055: Id1285 | B1055: 1975 | C1055: 1975 | D1055: Aug | E1055: Aug | F1055: 6 | G1055: 27612 | H1055: 1 | I1055: $8551.35 | J1055: tier - 2 | K1055: tier - 2 | L1055: R1011 | M1055: 51
A1056: Id1284 | B1056: 1975 | C1056: 1975 | D1056: Aug | E1056: Aug | F1056: 21 | G1056: 27627 | H1056: 1 | I1056: $8556.91 | J1056: tier - 2 | K1056: tier - 1 | L1056: R1011 | M1056: 51
A1057: Id1283 | B1057: 1988 | C1057: 1988 | D1057: Sep | E1057: Sep | F1057: 21 | G1057: 32407 | H1057: 3 | I1057: $8567.25 | J1057: tier - 2 | K1057: tier - 1 | L1057: R1012 | M1057: 38
A1058: Id1282 | B1058: 1975 | C1058: 1975 | D1058: Sep | E1058: Sep | F1058: 26 | G1058: 27663 | H1058: 1 | I1058: $8569.86 | J1058: tier - 2 | K1058: tier - 3 | L1058: R1013 | M1058: 51
A1059: Id1281 | B1059: 1982 | C1059: 1982 | D1059: Dec | E1059: Dec | F1059: 6 | G1059: 30291 | H1059: 3 | I1059: $8572.0400000000009 | J1059: tier - 2 | K1059: tier - 2 | L1059: R1021 | M1059: 44
A1060: Id1280 | B1060: 1987 | C1060: 1987 | D1060: Nov | E1060: Nov | F1060: 11 | G1060: 32092 | H1060: 3 | I1060: $8573.2999999999993 | J1060: tier - 2 | K1060: tier - 2 | L1060: R1021 | M1060: 39
A1061: Id1279 | B1061: 1983 | C1061: 1983 | D1061: Dec | E1061: Dec | F1061: 30 | G1061: 30680 | H1061: 5 | I1061: $8582.2999999999993 | J1061: tier - 2 | K1061: tier - 1 | L1061: R1013 | M1061: 43
A1062: Id1278 | B1062: 1983 | C1062: 1983 | D1062: Jul | E1062: Jul | F1062: 25 | G1062: 30522 | H1062: 5 | I1062: $8596.83 | J1062: tier - 2 | K1062: tier - 3 | L1062: R1013 | M1062: 43
A1063: Id1277 | B1063: 1973 | C1063: 1973 | D1063: Jul | E1063: Jul | F1063: 11 | G1063: 26856 | H1063: 0 | I1063: $8601.33 | J1063: tier - 2 | K1063: tier - 1 | L1063: R1013 | M1063: 53
A1064: Id1276 | B1064: 1977 | C1064: 1977 | D1064: Sep | E1064: Sep | F1064: 24 | G1064: 28392 | H1064: 2 | I1064: $8603.82 | J1064: tier - 2 | K1064: tier - 1 | L1064: R1019 | M1064: 49
A1065: Id1275 | B1065: 1977 | C1065: 1977 | D1065: Nov | E1065: Nov | F1065: 12 | G1065: 28441 | H1065: 2 | I1065: $8604.48 | J1065: tier - 3 | K1065: tier - 2 | L1065: R1016 | M1065: 49
A1066: Id1274 | B1066: 1977 | C1066: 1977 | D1066: Oct | E1066: Oct | F1066: 15 | G1066: 28413 | H1066: 3 | I1066: $8605.36 | J1066: tier - 2 | K1066: tier - 2 | L1066: R1013 | M1066: 49
... A2344: Id1 | B2344: 1968 | C2344: 1968 | D2344: Oct | E2344: Oct | F2344: 12 | G2344: 25123 | H2344: 0 | I2344: $63770.43 | J2344: tier - 1 | K2344: tier - 3 | L2344: R1013 | M2344: 58

Sheet Healthcare
A1: Customer ID | B1: First Name | C1: BMI | D1: HBA1C | E1: Heart Issues | F1: Any Transplants | G1: Cancer history | H1: NumberOfMajorSurgeries | I1: smoker | J1: Weight Status | K1: Diabetes Status | L1: Date of Birth | M1: $charges | N1: Hospital tier | O1: City tier | P1: State ID | Q1: Age
A2: Id2335 | B2: =VLOOKUP(Customer_Names!A2,Customer_Names!1:1048576,4,FALSE) -> Kelly | C2: =VLOOKUP(Medical_Examinations_2[[#This Row],[Customer ID]],Medical_Examinations!$1:$1048576,2,FALSE) -> 47.41 | D2: =VLOOKUP(Medical_Examinations_2[[#This Row],[Customer ID]],Medical_Examinations!$1:$1048576,4,FALSE) -> 7.47 | E2: =VLOOKUP(Medical_Examinations_2[[#This Row],[Customer ID]],Medical_Examinations!$1:$1048576,6,FALSE) -> No | F2: =VLOOKUP(Medical_Examinations_2[[#This Row],[Customer ID]],Medical_Examinations!$1:$1048576,7,FALSE) -> No | G2: =VLOOKUP(Medical_Examinations_2[[#This Row],[Customer ID]],Medical_Examinations!$1:$1048576,8,FALSE) -> No | H2: =VLOOKUP(Medical_Examinations_2[[#This Row],[Customer ID]],Medical_Examinations!$1:$1048576,9,FALSE) -> No major surgery | I2: =VLOOKUP(Medical_Examinations_2[[#This Row],[Customer ID]],Medical_Examinations!$1:$1048576,11,FALSE) -> Yes | J2: =VLOOKUP(Medical_Examinations_2[[#This Row],[Customer ID]],Medical_Examinations!$1:$1048576,3,FALSE) -> Obesity | K2: =VLOOKUP(Medical_Examinations_2[[#This Row],[Customer ID]],Medical_Examinations!$1:$1048576,5,FALSE) -> Diabetes | L2: =VLOOKUP(Hospitalisation_Details_2__3[[#This Row],[Customer ID]],Hospitalisation_Details_2__2!$1:$1048576,7,FALSE) -> 33794 | M2: =VLOOKUP(Hospitalisation_Details_2__3[[#This Row],[Customer ID]],Hospitalisation_Details_2__2!$1:$1048576,9,FALSE) -> $563.84 | N2: =VLOOKUP(Hospitalisation_Details_2__3[[#This Row],[Customer ID]],Hospitalisation_Details_2__2!$1:$1048576,10,FALSE) -> tier - 2 | O2: =VLOOKUP(Hospitalisation_Details_2__3[[#This Row],[Customer ID]],Hospitalisation_Details_2__2!$1:$1048576,11,FALSE) -> tier - 3 | P2: =VLOOKUP(Hospitalisation_Details_2__3[[#This Row],[Customer ID]],Hospitalisation_Details_2__2!$1:$1048576,12,FALSE) -> R1013 | Q2: =VLOOKUP(Hospitalisation_Details_2__3[[#This Row],[Customer ID]],Hospitalisation_Details_2__2!$1:$1048576,13,FALSE) -> 34
A3: Id2334 | B3: =VLOOKUP(Customer_Names!A3,Customer_Names!$1:$1048576,4,FALSE) -> Matthew D | C3: =VLOOKUP(Medical_Examinations_2[[#This Row],[Customer ID]],Medical_Examinations!$1:$1048576,2,FALSE) -> 30.36 | D3: =VLOOKUP(Medical_Examinations_2[[#This Row],[Customer ID]],Medical_Examinations!$1:$1048576,4,FALSE) -> 5.77 | E3: =VLOOKUP(Medical_Examinations_2[[#This Row],[Customer ID]],Medical_Examinations!$1:$1048576,6,FALSE) -> No | F3: =VLOOKUP(Medical_Examinations_2[[#This Row],[Customer ID]],Medical_Examinations!$1:$1048576,7,FALSE) -> No | G3: =VLOOKUP(Medical_Examinations_2[[#This Row],[Customer ID]],Medical_Examinations!$1:$1048576,8,FALSE) -> No | H3: =VLOOKUP(Medical_Examinations_2[[#This Row],[Customer ID]],Medical_Examinations!$1:$1048576,9,FALSE) -> No major surgery | I3: =VLOOKUP(Medical_Examinations_2[[#This Row],[Customer ID]],Medical_Examinations!$1:$1048576,11,FALSE) -> Yes | J3: =VLOOKUP(Medical_Examinations_2[[#This Row],[Customer ID]],Medical_Examinations!$1:$1048576,3,FALSE) -> Obesity | K3: =VLOOKUP(Medical_Examinations_2[[#This Row],[Customer ID]],Medical_Examinations!$1:$1048576,5,FALSE) -> Prediabetes | L3: =VLOOKUP(Hospitalisation_Details_2__3[[#This Row],[Customer ID]],Hospitalisation_Details_2__2!$1:$1048576,7,FALSE) -> 33938 | M3: =VLOOKUP(Hospitalisation_Details_2__3[[#This Row],[Customer ID]],Hospitalisation_Details_2__2!$1:$1048576,9,FALSE) -> $570.62 | N3: =VLOOKUP(Hospitalisation_Details_2__3[[#This Row],[Customer ID]],Hospitalisation_Details_2__2!$1:$1048576,10,FALSE) -> tier - 2 | O3: =VLOOKUP(Hospitalisation_Details_2__3[[#This Row],[Customer ID]],Hospitalisation_Details_2__2!$1:$1048576,11,FALSE) -> tier - 1 | P3: =VLOOKUP(Hospitalisation_Details_2__3[[#This Row],[Customer ID]],Hospitalisation_Details_2__2!$1:$1048576,12,FALSE) -> R1013 | Q3: =VLOOKUP(Hospitalisation_Details_2__3[[#This Row],[Customer ID]],Hospitalisation_Details_2__2!$1:$1048576,13,FALSE) -> 34
A4: Id2333 | B4: =VLOOKUP(Customer_Names!A4,Customer_Names!$1:$1048576,4,FALSE) -> Phil | C4: =VLOOKUP(Medical_Examinations_2[[#This Row],[Customer ID]],Medical_Examinations!$1:$1048576,2,FALSE) -> 34.485 | D4: =VLOOKUP(Medical_Examinations_2[[#This Row],[Customer ID]],Medical_Examinations!$1:$1048576,4,FALSE) -> 11.87 | E4: =VLOOKUP(Medical_Examinations_2[[#This Row],[Customer ID]],Medical_Examinations!$1:$1048576,6,FALSE) -> Yes | F4: =VLOOKUP(Medical_Examinations_2[[#This Row],[Customer ID]],Medical_Examinations!$1:$1048576,7,FALSE) -> No | G4: =VLOOKUP(Medical_Examinations_2[[#This Row],[Customer ID]],Medical_Examinations!$1:$1048576,8,FALSE) -> No | H4: =VLOOKUP(Medical_Examinations_2[[#This Row],[Customer ID]],Medical_Examinations!$1:$1048576,9,FALSE) -> 2 | I4: =VLOOKUP(Medical_Examinations_2[[#This Row],[Customer ID]],Medical_Examinations!$1:$1048576,11,FALSE) -> Yes | J4: =VLOOKUP(Medical_Examinations_2[[#This Row],[Customer ID]],Medical_Examinations!$1:$1048576,3,FALSE) -> Obesity | K4: =VLOOKUP(Medical_Examinations_2[[#This Row],[Customer ID]],Medical_Examinations!$1:$1048576,5,FALSE) -> Diabetes | L4: =VLOOKUP(Hospitalisation_Details_2__3[[#This Row],[Customer ID]],Hospitalisation_Details_2__2!$1:$1048576,7,FALSE) -> 34150 | M4: =VLOOKUP(Hospitalisation_Details_2__3[[#This Row],[Customer ID]],Hospitalisation_Details_2__2!$1:$1048576,9,FALSE) -> $600 | N4: =VLOOKUP(Hospitalisation_Details_2__3[[#This Row],[Customer ID]],Hospitalisation_Details_2__2!$1:$1048576,10,FALSE) -> tier - 2 | O4: =VLOOKUP(Hospitalisation_Details_2__3[[#This Row],[Customer ID]],Hospitalisation_Details_2__2!$1:$1048576,11,FALSE) -> tier - 1 | P4: =VLOOKUP(Hospitalisation_Details_2__3[[#This Row],[Customer ID]],Hospitalisation_Details_2__2!$1:$1048576,12,FALSE) -> R1013 | Q4: =VLOOKUP(Hospitalisation_Details_2__3[[#This Row],[Customer ID]],Hospitalisation_Details_2__2!$1:$1048576,13,FALSE) -> 33
A5: Id2332 | B5: =VLOOKUP(Customer_Names!A5,Customer_Names!$1:$1048576,4,FALSE) -> Kelsey | C5: =VLOOKUP(Medical_Examinations_2[[#This Row],[Customer ID]],Medical_Examinations!$1:$1048576,2,FALSE) -> 38.095 | D5: =VLOOKUP(Medical_Examinations_2[[#This Row],[Customer ID]],Medical_Examinations!$1:$1048576,4,FALSE) -> 6.05 | E5: =VLOOKUP(Medical_Examinations_2[[#This Row],[Customer ID]],Medical_Examinations!$1:$1048576,6,FALSE) -> No | F5: =VLOOKUP(Medical_Examinations_2[[#This Row],[Customer ID]],Medical_Examinations!$1:$1048576,7,FALSE) -> No | G5: =VLOOKUP(Medical_Examinations_2[[#This Row],[Customer ID]],Medical_Examinations!$1:$1048576,8,FALSE) -> No | H5: =VLOOKUP(Medical_Examinations_2[[#This Row],[Customer ID]],Medical_Examinations!$1:$1048576,9,FALSE) -> No major surgery | I5: =VLOOKUP(Medical_Examinations_2[[#This Row],[Customer ID]],Medical_Examinations!$1:$1048576,11,FALSE) -> Yes | J5: =VLOOKUP(Medical_Examinations_2[[#This Row],[Customer ID]],Medical_Examinations!$1:$1048576,3,FALSE) -> Obesity | K5: =VLOOKUP(Medical_Examinations_2[[#This Row],[Customer ID]],Medical_Examinations!$1:$1048576,5,FALSE) -> Prediabetes | L5: =VLOOKUP(Hospitalisation_Details_2__3[[#This Row],[Customer ID]],Hospitalisation_Details_2__2!$1:$1048576,7,FALSE) -> 33860 | M5: =VLOOKUP(Hospitalisation_Details_2__3[[#This Row],[Customer ID]],Hospitalisation_Details_2__2!$1:$1048576,9,FALSE) -> $604.54 | N5: =VLOOKUP(Hospitalisation_Details_2__3[[#This Row],[Customer ID]],Hospitalisation_Details_2__2!$1:$1048576,10,FALSE) -> tier - 3 | O5: =VLOOKUP(Hospitalisation_Details_2__3[[#This Row],[Customer ID]],Hospitalisation_Details_2__2!$1:$1048576,11,FALSE) -> tier - 3 | P5: =VLOOKUP(Hospitalisation_Details_2__3[[#This Row],[Customer ID]],Hospitalisation_Details_2__2!$1:$1048576,12,FALSE) -> R1013 | Q5: =VLOOKUP(Hospitalisation_Details_2__3[[#This Row],[Customer ID]],Hospitalisation_Details_2__2!$1:$1048576,13,FALSE) -> 34
A6: Id2331 | B6: =VLOOKUP(Customer_Names!A6,Customer_Names!$1:$1048576,4,FALSE) -> Kristyn | C6: =VLOOKUP(Medical_Examinations_2[[#This Row],[Customer ID]],Medical_Examinations!$1:$1048576,2,FALSE) -> 35.53 | D6: =VLOOKUP(Medical_Examinations_2[[#This Row],[Customer ID]],Medical_Examinations!$1:$1048576,4,FALSE) -> 5.45 | E6: =VLOOKUP(Medical_Examinations_2[[#This Row],[Customer ID]],Medical_Examinations!$1:$1048576,6,FALSE) -> No | F6: =VLOOKUP(Medical_Examinations_2[[#This Row],[Customer ID]],Medical_Examinations!$1:$1048576,7,FALSE) -> No | G6: =VLOOKUP(Medical_Examinations_2[[#This Row],[Customer ID]],Medical_Examinations!$1:$1048576,8,FALSE) -> No | H6: =VLOOKUP(Medical_Examinations_2[[#This Row],[Customer ID]],Medical_Examinations!$1:$1048576,9,FALSE) -> No major surgery | I6: =VLOOKUP(Medical_Examinations_2[[#This Row],[Customer ID]],Medical_Examinations!$1:$1048576,11,FALSE) -> Yes | J6: =VLOOKUP(Medical_Examinations_2[[#This Row],[Customer ID]],Medical_Examinations!$1:$1048576,3,FALSE) -> Obesity | K6: =VLOOKUP(Medical_Examinations_2[[#This Row],[Customer ID]],Medical_Examinations!$1:$1048576,5,FALSE) -> Normal | L6: =VLOOKUP(Hospitalisation_Details_2__3[[#This Row],[Customer ID]],Hospitalisation_Details_2__2!$1:$1048576,7,FALSE) -> 36003 | M6: =VLOOKUP(Hospitalisation_Details_2__3[[#This Row],[Customer ID]],Hospitalisation_Details_2__2!$1:$1048576,9,FALSE) -> $637.26 | N6: =VLOOKUP(Hospitalisation_Details_2__3[[#This Row],[Customer ID]],Hospitalisation_Details_2__2!$1:$1048576,10,FALSE) -> tier - 3 | O6: =VLOOKUP(Hospitalisation_Details_2__3[[#This Row],[Customer ID]],Hospitalisation_Details_2__2!$1:$1048576,11,FALSE) -> tier - 3 | P6: =VLOOKUP(Hospitalisation_Details_2__3[[#This Row],[Customer ID]],Hospitalisation_Details_2__2!$1:$1048576,12,FALSE) -> R1013 | Q6: =VLOOKUP(Hospitalisation_Details_2__3[[#This Row],[Customer ID]],Hospitalisation_Details_2__2!$1:$1048576,13,FALSE) -> 28
A7: Id2330 | B7: =VLOOKUP(Customer_Names!A7,Customer_Names!$1:$1048576,4,FALSE) -> Russell B. | C7: =VLOOKUP(Medical_Examinations_2[[#This Row],[Customer ID]],Medical_Examinations!$1:$1048576,2,FALSE) -> 32.8 | D7: =VLOOKUP(Medical_Examinations_2[[#This Row],[Customer ID]],Medical_Examinations!$1:$1048576,4,FALSE) -> 6.59 | E7: =VLOOKUP(Medical_Examinations_2[[#This Row],[Customer ID]],Medical_Examinations!$1:$1048576,6,FALSE) -> No | F7: =VLOOKUP(Medical_Examinations_2[[#This Row],[Customer ID]],Medical_Examinations!$1:$1048576,7,FALSE) -> No | G7: =VLOOKUP(Medical_Examinations_2[[#This Row],[Customer ID]],Medical_Examinations!$1:$1048576,8,FALSE) -> No | H7: =VLOOKUP(Medical_Examinations_2[[#This Row],[Customer ID]],Medical_Examinations!$1:$1048576,9,FALSE) -> No major surgery | I7: =VLOOKUP(Medical_Examinations_2[[#This Row],[Customer ID]],Medical_Examinations!$1:$1048576,11,FALSE) -> Yes | J7: =VLOOKUP(Medical_Examinations_2[[#This Row],[Customer ID]],Medical_Examinations!$1:$1048576,3,FALSE) -> Obesity | K7: =VLOOKUP(Medical_Examinations_2[[#This Row],[Customer ID]],Medical_Examinations!$1:$1048576,5,FALSE) -> Diabetes | L7: =VLOOKUP(Hospitalisation_Details_2__3[[#This Row],[Customer ID]],Hospitalisation_Details_2__2!$1:$1048576,7,FALSE) -> 37215 | M7: =VLOOKUP(Hospitalisation_Details_2__3[[#This Row],[Customer ID]],Hospitalisation_Details_2__2!$1:$1048576,9,FALSE) -> $646.14 | N7: =VLOOKUP(Hospitalisation_Details_2__3[[#This Row],[Customer ID]],Hospitalisation_Details_2__2!$1:$1048576,10,FALSE) -> tier - 3 | O7: =VLOOKUP(Hospitalisation_Details_2__3[[#This Row],[Customer ID]],Hospitalisation_Details_2__2!$1:$1048576,11,FALSE) -> tier - 3 | P7: =VLOOKUP(Hospitalisation_Details_2__3[[#This Row],[Customer ID]],Hospitalisation_Details_2__2!$1:$1048576,12,FALSE) -> R1012 | Q7: =VLOOKUP(Hospitalisation_Details_2__3[[#This Row],[Customer ID]],Hospitalisation_Details_2__2!$1:$1048576,13,FALSE) -> 25
A8: Id2329 | B8: =VLOOKUP(Customer_Names!A8,Customer_Names!$1:$1048576,4,FALSE) -> Scott | C8: =VLOOKUP(Medical_Examinations_2[[#This Row],[Customer ID]],Medical_Examinations!$1:$1048576,2,FALSE) -> 36.4 | D8: =VLOOKUP(Medical_Examinations_2[[#This Row],[Customer ID]],Medical_Examinations!$1:$1048576,4,FALSE) -> 6.07 | E8: =VLOOKUP(Medical_Examinations_2[[#This Row],[Customer ID]],Medical_Examinations!$1:$1048576,6,FALSE) -> No | F8: =VLOOKUP(Medical_Examinations_2[[#This Row],[Customer ID]],Medical_Examinations!$1:$1048576,7,FALSE) -> No | G8: =VLOOKUP(Medical_Examinations_2[[#This Row],[Customer ID]],Medical_Examinations!$1:$1048576,8,FALSE) -> No | H8: =VLOOKUP(Medical_Examinations_2[[#This Row],[Customer ID]],Medical_Examinations!$1:$1048576,9,FALSE) -> No major surgery | I8: =VLOOKUP(Medical_Examinations_2[[#This Row],[Customer ID]],Medical_Examinations!$1:$1048576,11,FALSE) -> Yes | J8: =VLOOKUP(Medical_Examinations_2[[#This Row],[Customer ID]],Medical_Examinations!$1:$1048576,3,FALSE) -> Obesity | K8: =VLOOKUP(Medical_Examinations_2[[#This Row],[Customer ID]],Medical_Examinations!$1:$1048576,5,FALSE) -> Prediabetes | L8: =VLOOKUP(Hospitalisation_Details_2__3[[#This Row],[Customer ID]],Hospitalisation_Details_2__2!$1:$1048576,7,FALSE) -> 34121 | M8: =VLOOKUP(Hospitalisation_Details_2__3[[#This Row],[Customer ID]],Hospitalisation_Details_2__2!$1:$1048576,9,FALSE) -> $650 | N8: =VLOOKUP(Hospitalisation_Details_2__3[[#This Row],[Customer ID]],Hospitalisation_Details_2__2!$1:$1048576,10,FALSE) -> tier - 3 | O8: =VLOOKUP(Hospitalisation_Details_2__3[[#This Row],[Customer ID]],Hospitalisation_Details_2__2!$1:$1048576,11,FALSE) -> tier - 3 | P8: =VLOOKUP(Hospitalisation_Details_2__3[[#This Row],[Customer ID]],Hospitalisation_Details_2__2!$1:$1048576,12,FALSE) -> R1013 | Q8: =VLOOKUP(Hospitalisation_Details_2__3[[#This Row],[Customer ID]],Hospitalisation_Details_2__2!$1:$1048576,13,FALSE) -> 33
A9: Id2328 | B9: =VLOOKUP(Customer_Names!A9,Customer_Names!$1:$1048576,4,FALSE) -> Stephen | C9: =VLOOKUP(Medical_Examinations_2[[#This Row],[Customer ID]],Medical_Examinations!$1:$1048576,2,FALSE) -> 36.96 | D9: =VLOOKUP(Medical_Examinations_2[[#This Row],[Customer ID]],Medical_Examinations!$1:$1048576,4,FALSE) -> 7.93 | E9: =VLOOKUP(Medical_Examinations_2[[#This Row],[Customer ID]],Medical_Examinations!$1:$1048576,6,FALSE) -> No | F9: =VLOOKUP(Medical_Examinations_2[[#This Row],[Customer ID]],Medical_Examinations!$1:$1048576,7,FALSE) -> No | G9: =VLOOKUP(Medical_Examinations_2[[#This Row],[Customer ID]],Medical_Examinations!$1:$1048576,8,FALSE) -> No | H9: =VLOOKUP(Medical_Examinations_2[[#This Row],[Customer ID]],Medical_Examinations!$1:$1048576,9,FALSE) -> 3 | I9: =VLOOKUP(Medical_Examinations_2[[#This Row],[Customer ID]],Medical_Examinations!$1:$1048576,11,FALSE) -> Yes | J9: =VLOOKUP(Medical_Examinations_2[[#This Row],[Customer ID]],Medical_Examinations!$1:$1048576,3,FALSE) -> Obesity | K9: =VLOOKUP(Medical_Examinations_2[[#This Row],[Customer ID]],Medical_Examinations!$1:$1048576,5,FALSE) -> Diabetes | L9: =VLOOKUP(Hospitalisation_Details_2__3[[#This Row],[Customer ID]],Hospitalisation_Details_2__2!$1:$1048576,7,FALSE) -> 34884 | M9: =VLOOKUP(Hospitalisation_Details_2__3[[#This Row],[Customer ID]],Hospitalisation_Details_2__2!$1:$1048576,9,FALSE) -> $650 | N9: =VLOOKUP(Hospitalisation_Details_2__3[[#This Row],[Customer ID]],Hospitalisation_Details_2__2!$1:$1048576,10,FALSE) -> tier - 3 | O9: =VLOOKUP(Hospitalisation_Details_2__3[[#This Row],[Customer ID]],Hospitalisation_Details_2__2!$1:$1048576,11,FALSE) -> tier - 3 | P9: =VLOOKUP(Hospitalisation_Details_2__3[[#This Row],[Customer ID]],Hospitalisation_Details_2__2!$1:$1048576,12,FALSE) -> R1013 | Q9: =VLOOKUP(Hospitalisation_Details_2__3[[#This Row],[Customer ID]],Hospitalisation_Details_2__2!$1:$1048576,13,FALSE) -> 31
A10: Id2327 | B10: =VLOOKUP(Customer_Names!A10,Customer_Names!$1:$1048576,4,FALSE) -> Patrick R. | C10: =VLOOKUP(Medical_Examinations_2[[#This Row],[Customer ID]],Medical_Examinations!$1:$1048576,2,FALSE) -> 41.14 | D10: =VLOOKUP(Medical_Examinations_2[[#This Row],[Customer ID]],Medical_Examinations!$1:$1048576,4,FALSE) -> 9.58 | E10: =VLOOKUP(Medical_Examinations_2[[#This Row],[Customer ID]],Medical_Examinations!$1:$1048576,6,FALSE) -> Yes | F10: =VLOOKUP(Medical_Examinations_2[[#This Row],[Customer ID]],Medical_Examinations!$1:$1048576,7,FALSE) -> No | G10: =VLOOKUP(Medical_Examinations_2[[#This Row],[Customer ID]],Medical_Examinations!$1:$1048576,8,FALSE) -> Yes | H10: =VLOOKUP(Medical_Examinations_2[[#This Row],[Customer ID]],Medical_Examinations!$1:$1048576,9,FALSE) -> 1 | I10: =VLOOKUP(Medical_Examinations_2[[#This Row],[Customer ID]],Medical_Examinations!$1:$1048576,11,FALSE) -> Yes | J10: =VLOOKUP(Medical_Examinations_2[[#This Row],[Customer ID]],Medical_Examinations!$1:$1048576,3,FALSE) -> Obesity | K10: =VLOOKUP(Medical_Examinations_2[[#This Row],[Customer ID]],Medical_Examinations!$1:$1048576,5,FALSE) -> Diabetes | L10: =VLOOKUP(Hospitalisation_Details_2__3[[#This Row],[Customer ID]],Hospitalisation_Details_2__2!$1:$1048576,7,FALSE) -> 37589 | M10: =VLOOKUP(Hospitalisation_Details_2__3[[#This Row],[Customer ID]],Hospitalisation_Details_2__2!$1:$1048576,9,FALSE) -> $668 | N10: =VLOOKUP(Hospitalisation_Details_2__3[[#This Row],[Customer ID]],Hospitalisation_Details_2__2!$1:$1048576,10,FALSE) -> tier - 3 | O10: =VLOOKUP(Hospitalisation_Details_2__3[[#This Row],[Customer ID]],Hospitalisation_Details_2__2!$1:$1048576,11,FALSE) -> tier - 2 | P10: =VLOOKUP(Hospitalisation_Details_2__3[[#This Row],[Customer ID]],Hospitalisation_Details_2__2!$1:$1048576,12,FALSE) -> R1012 | Q10: =VLOOKUP(Hospitalisation_Details_2__3[[#This Row],[Customer ID]],Hospitalisation_Details_2__2!$1:$1048576,13,FALSE) -> 24
A11: Id2326 | B11: =VLOOKUP(Customer_Names!A11,Customer_Names!$1:$1048576,4,FALSE) -> Brooke N. | C11: =VLOOKUP(Medical_Examinations_2[[#This Row],[Customer ID]],Medical_Examinations!$1:$1048576,2,FALSE) -> 38.06 | D11: =VLOOKUP(Medical_Examinations_2[[#This Row],[Customer ID]],Medical_Examinations!$1:$1048576,4,FALSE) -> 10.79 | E11: =VLOOKUP(Medical_Examinations_2[[#This Row],[Customer ID]],Medical_Examinations!$1:$1048576,6,FALSE) -> No | F11: =VLOOKUP(Medical_Examinations_2[[#This Row],[Customer ID]],Medical_Examinations!$1:$1048576,7,FALSE) -> No | G11: =VLOOKUP(Medical_Examinations_2[[#This Row],[Customer ID]],Medical_Examinations!$1:$1048576,8,FALSE) -> No | H11: =VLOOKUP(Medical_Examinations_2[[#This Row],[Customer ID]],Medical_Examinations!$1:$1048576,9,FALSE) -> No major surgery | I11: =VLOOKUP(Medical_Examinations_2[[#This Row],[Customer ID]],Medical_Examinations!$1:$1048576,11,FALSE) -> Yes | J11: =VLOOKUP(Medical_Examinations_2[[#This Row],[Customer ID]],Medical_Examinations!$1:$1048576,3,FALSE) -> Obesity | K11: =VLOOKUP(Medical_Examinations_2[[#This Row],[Customer ID]],Medical_Examinations!$1:$1048576,5,FALSE) -> Diabetes | L11: =VLOOKUP(Hospitalisation_Details_2__3[[#This Row],[Customer ID]],Hospitalisation_Details_2__2!$1:$1048576,7,FALSE) -> 35743 | M11: =VLOOKUP(Hospitalisation_Details_2__3[[#This Row],[Customer ID]],Hospitalisation_Details_2__2!$1:$1048576,9,FALSE) -> $670 | N11: =VLOOKUP(Hospitalisation_Details_2__3[[#This Row],[Customer ID]],Hospitalisation_Details_2__2!$1:$1048576,10,FALSE) -> tier - 3 | O11: =VLOOKUP(Hospitalisation_Details_2__3[[#This Row],[Customer ID]],Hospitalisation_Details_2__2!$1:$1048576,11,FALSE) -> tier - 3 | P11: =VLOOKUP(Hospitalisation_Details_2__3[[#This Row],[Customer ID]],Hospitalisation_Details_2__2!$1:$1048576,12,FALSE) -> R1013 | Q11: =VLOOKUP(Hospitalisation_Details_2__3[[#This Row],[Customer ID]],Hospitalisation_Details_2__2!$1:$1048576,13,FALSE) -> 29
A12: Id2325 | B12: =VLOOKUP(Customer_Names!A12,Customer_Names!$1:$1048576,4,FALSE) -> Ms. Paola Andrea | C12: =VLOOKUP(Medical_Examinations_2[[#This Row],[Customer ID]],Medical_Examinations!$1:$1048576,2,FALSE) -> 37.7 | D12: =VLOOKUP(Medical_Examinations_2[[#This Row],[Customer ID]],Medical_Examinations!$1:$1048576,4,FALSE) -> 5.96 | E12: =VLOOKUP(Medical_Examinations_2[[#This Row],[Customer ID]],Medical_Examinations!$1:$1048576,6,FALSE) -> Yes | F12: =VLOOKUP(Medical_Examinations_2[[#This Row],[Customer ID]],Medical_Examinations!$1:$1048576,7,FALSE) -> No | G12: =VLOOKUP(Medical_Examinations_2[[#This Row],[Customer ID]],Medical_Examinations!$1:$1048576,8,FALSE) -> No | H12: =VLOOKUP(Medical_Examinations_2[[#This Row],[Customer ID]],Medical_Examinations!$1:$1048576,9,FALSE) -> 2 | I12: =VLOOKUP(Medical_Examinations_2[[#This Row],[Customer ID]],Medical_Examinations!$1:$1048576,11,FALSE) -> Yes | J12: =VLOOKUP(Medical_Examinations_2[[#This Row],[Customer ID]],Medical_Examinations!$1:$1048576,3,FALSE) -> Obesity | K12: =VLOOKUP(Medical_Examinations_2[[#This Row],[Customer ID]],Medical_Examinations!$1:$1048576,5,FALSE) -> Prediabetes | L12: =VLOOKUP(Hospitalisation_Details_2__3[[#This Row],[Customer ID]],Hospitalisation_Details_2__2!$1:$1048576,7,FALSE) -> 37146 | M12: =VLOOKUP(Hospitalisation_Details_2__3[[#This Row],[Customer ID]],Hospitalisation_Details_2__2!$1:$1048576,9,FALSE) -> $687.54 | N12: =VLOOKUP(Hospitalisation_Details_2__3[[#This Row],[Customer ID]],Hospitalisation_Details_2__2!$1:$1048576,10,FALSE) -> tier - 3 | O12: =VLOOKUP(Hospitalisation_Details_2__3[[#This Row],[Customer ID]],Hospitalisation_Details_2__2!$1:$1048576,11,FALSE) -> tier - 2 | P12: =VLOOKUP(Hospitalisation_Details_2__3[[#This Row],[Customer ID]],Hospitalisation_Details_2__2!$1:$1048576,12,FALSE) -> R1013 | Q12: =VLOOKUP(Hospitalisation_Details_2__3[[#This Row],[Customer ID]],Hospitalisation_Details_2__2!$1:$1048576,13,FALSE) -> 25
A13: Id2324 | B13: =VLOOKUP(Customer_Names!A13,Customer_Names!$1:$1048576,4,FALSE) -> David | C13: =VLOOKUP(Medical_Examinations_2[[#This Row],[Customer ID]],Medical_Examinations!$1:$1048576,2,FALSE) -> 42.13 | D13: =VLOOKUP(Medical_Examinations_2[[#This Row],[Customer ID]],Medical_Examinations!$1:$1048576,4,FALSE) -> 11.9 | E13: =VLOOKUP(Medical_Examinations_2[[#This Row],[Customer ID]],Medical_Examinations!$1:$1048576,6,FALSE) -> No | F13: =VLOOKUP(Medical_Examinations_2[[#This Row],[Customer ID]],Medical_Examinations!$1:$1048576,7,FALSE) -> No | G13: =VLOOKUP(Medical_Examinations_2[[#This Row],[Customer ID]],Medical_Examinations!$1:$1048576,8,FALSE) -> No | H13: =VLOOKUP(Medical_Examinations_2[[#This Row],[Customer ID]],Medical_Examinations!$1:$1048576,9,FALSE) -> No major surgery | I13: =VLOOKUP(Medical_Examinations_2[[#This Row],[Customer ID]],Medical_Examinations!$1:$1048576,11,FALSE) -> Yes | J13: =VLOOKUP(Medical_Examinations_2[[#This Row],[Customer ID]],Medical_Examinations!$1:$1048576,3,FALSE) -> Obesity | K13: =VLOOKUP(Medical_Examinations_2[[#This Row],[Customer ID]],Medical_Examinations!$1:$1048576,5,FALSE) -> Diabetes | L13: =VLOOKUP(Hospitalisation_Details_2__3[[#This Row],[Customer ID]],Hospitalisation_Details_2__2!$1:$1048576,7,FALSE) -> 36520 | M13: =VLOOKUP(Hospitalisation_Details_2__3[[#This Row],[Customer ID]],Hospitalisation_Details_2__2!$1:$1048576,9,FALSE) -> $700 | N13: =VLOOKUP(Hospitalisation_Details_2__3[[#This Row],[Customer ID]],Hospitalisation_Details_2__2!$1:$1048576,10,FALSE) -> tier-2 | O13: =VLOOKUP(Hospitalisation_Details_2__3[[#This Row],[Customer ID]],Hospitalisation_Details_2__2!$1:$1048576,11,FALSE) -> tier - 3 | P13: =VLOOKUP(Hospitalisation_Details_2__3[[#This Row],[Customer ID]],Hospitalisation_Details_2__2!$1:$1048576,12,FALSE) -> R1013 | Q13: =VLOOKUP(Hospitalisation_Details_2__3[[#This Row],[Customer ID]],Hospitalisation_Details_2__2!$1:$1048576,13,FALSE) -> 27
A14: Id2323 | B14: =VLOOKUP(Customer_Names!A14,Customer_Names!$1:$1048576,4,FALSE) -> Wade | C14: =VLOOKUP(Medical_Examinations_2[[#This Row],[Customer ID]],Medical_Examinations!$1:$1048576,2,FALSE) -> 40.92 | D14: =VLOOKUP(Medical_Examinations_2[[#This Row],[Customer ID]],Medical_Examinations!$1:$1048576,4,FALSE) -> 8.41 | E14: =VLOOKUP(Medical_Examinations_2[[#This Row],[Customer ID]],Medical_Examinations!$1:$1048576,6,FALSE) -> No | F14: =VLOOKUP(Medical_Examinations_2[[#This Row],[Customer ID]],Medical_Examinations!$1:$1048576,7,FALSE) -> No | G14: =VLOOKUP(Medical_Examinations_2[[#This Row],[Customer ID]],Medical_Examinations!$1:$1048576,8,FALSE) -> No | H14: =VLOOKUP(Medical_Examinations_2[[#This Row],[Customer ID]],Medical_Examinations!$1:$1048576,9,FALSE) -> No major surgery | I14: =VLOOKUP(Medical_Examinations_2[[#This Row],[Customer ID]],Medical_Examinations!$1:$1048576,11,FALSE) -> Yes | J14: =VLOOKUP(Medical_Examinations_2[[#This Row],[Customer ID]],Medical_Examinations!$1:$1048576,3,FALSE) -> Obesity | K14: =VLOOKUP(Medical_Examinations_2[[#This Row],[Customer ID]],Medical_Examinations!$1:$1048576,5,FALSE) -> Diabetes | L14: =VLOOKUP(Hospitalisation_Details_2__3[[#This Row],[Customer ID]],Hospitalisation_Details_2__2!$1:$1048576,7,FALSE) -> 36508 | M14: =VLOOKUP(Hospitalisation_Details_2__3[[#This Row],[Customer ID]],Hospitalisation_Details_2__2!$1:$1048576,9,FALSE) -> $722.99 | N14: =VLOOKUP(Hospitalisation_Details_2__3[[#This Row],[Customer ID]],Hospitalisation_Details_2__2!$1:$1048576,10,FALSE) -> tier - 3 | O14: =VLOOKUP(Hospitalisation_Details_2__3[[#This Row],[Customer ID]],Hospitalisation_Details_2__2!$1:$1048576,11,FALSE) -> tier - 1 | P14: =VLOOKUP(Hospitalisation_Details_2__3[[#This Row],[Customer ID]],Hospitalisation_Details_2__2!$1:$1048576,12,FALSE) -> R1013 | Q14: =VLOOKUP(Hospitalisation_Details_2__3[[#This Row],[Customer ID]],Hospitalisation_Details_2__2!$1:$1048576,13,FALSE) -> 27
... A25: Id2312 | B25: =VLOOKUP(Customer_Names!A25,Customer_Names!$1:$1048576,4,FALSE) -> Eric A. | C25: =VLOOKUP(Medical_Examinations_2[[#This Row],[Customer ID]],Medical_Examinations!$1:$1048576,2,FALSE) -> 41.8 | D25: =VLOOKUP(Medical_Examinations_2[[#This Row],[Customer ID]],Medical_Examinations!$1:$1048576,4,FALSE) -> 7.89 | E25: =VLOOKUP(Medical_Examinations_2[[#This Row],[Customer ID]],Medical_Examinations!$1:$1048576,6,FALSE) -> Yes | F25: =VLOOKUP(Medical_Examinations_2[[#This Row],[Customer ID]],Medical_Examinations!$1:$1048576,7,FALSE) -> No | G25: =VLOOKUP(Medical_Examinations_2[[#This Row],[Customer ID]],Medical_Examinations!$1:$1048576,8,FALSE) -> No | H25: =VLOOKUP(Medical_Examinations_2[[#This Row],[Customer ID]],Medical_Examinations!$1:$1048576,9,FALSE) -> 2 | I25: =VLOOKUP(Medical_Examinations_2[[#This Row],[Customer ID]],Medical_Examinations!$1:$1048576,11,FALSE) -> Yes | J25: =VLOOKUP(Medical_Examinations_2[[#This Row],[Customer ID]],Medical_Examinations!$1:$1048576,3,FALSE) -> Obesity | K25: =VLOOKUP(Medical_Examinations_2[[#This Row],[Customer ID]],Medical_Examinations!$1:$1048576,5,FALSE) -> Diabetes | L25: =VLOOKUP(Hospitalisation_Details_2__3[[#This Row],[Customer ID]],Hospitalisation_Details_2__2!$1:$1048576,7,FALSE) -> 35000 | M25: =VLOOKUP(Hospitalisation_Details_2__3[[#This Row],[Customer ID]],Hospitalisation_Details_2__2!$1:$1048576,9,FALSE) -> $928.59 | N25: =VLOOKUP(Hospitalisation_Details_2__3[[#This Row],[Customer ID]],Hospitalisation_Details_2__2!$1:$1048576,10,FALSE) -> tier - 3 | O25: =VLOOKUP(Hospitalisation_Details_2__3[[#This Row],[Customer ID]],Hospitalisation_Details_2__2!$1:$1048576,11,FALSE) -> tier - 1 | P25: =VLOOKUP(Hospitalisation_Details_2__3[[#This Row],[Customer ID]],Hospitalisation_Details_2__2!$1:$1048576,12,FALSE) -> R1013 | Q25: =VLOOKUP(Hospitalisation_Details_2__3[[#This Row],[Customer ID]],Hospitalisation_Details_2__2!$1:$1048576,13,FALSE) -> 31
A26: Id2311 | B26: =VLOOKUP(Customer_Names!A26,Customer_Names!$1:$1048576,4,FALSE) -> Emiliano I. | C26: =VLOOKUP(Medical_Examinations_2[[#This Row],[Customer ID]],Medical_Examinations!$1:$1048576,2,FALSE) -> 35.09 | D26: =VLOOKUP(Medical_Examinations_2[[#This Row],[Customer ID]],Medical_Examinations!$1:$1048576,4,FALSE) -> 4.38 | E26: =VLOOKUP(Medical_Examinations_2[[#This Row],[Customer ID]],Medical_Examinations!$1:$1048576,6,FALSE) -> Yes | F26: =VLOOKUP(Medical_Examinations_2[[#This Row],[Customer ID]],Medical_Examinations!$1:$1048576,7,FALSE) -> No | H26: =VLOOKUP(Medical_Examinations_2[[#This Row],[Customer ID]],Medical_Examinations!$1:$1048576,9,FALSE) -> 2 | I26: =VLOOKUP(Medical_Examinations_2[[#This Row],[Customer ID]],Medical_Examinations!$1:$1048576,11,FALSE) -> Yes | J26: =VLOOKUP(Medical_Examinations_2[[#This Row],[Customer ID]],Medical_Examinations!$1:$1048576,3,FALSE) -> Obesity | K26: =VLOOKUP(Medical_Examinations_2[[#This Row],[Customer ID]],Medical_Examinations!$1:$1048576,5,FALSE) -> Normal | L26: =VLOOKUP(Hospitalisation_Details_2__3[[#This Row],[Customer ID]],Hospitalisation_Details_2__2!$1:$1048576,7,FALSE) -> 37122 | M26: =VLOOKUP(Hospitalisation_Details_2__3[[#This Row],[Customer ID]],Hospitalisation_Details_2__2!$1:$1048576,9,FALSE) -> $964.71 | N26: =VLOOKUP(Hospitalisation_Details_2__3[[#This Row],[Customer ID]],Hospitalisation_Details_2__2!$1:$1048576,10,FALSE) -> tier - 3 | O26: =VLOOKUP(Hospitalisation_Details_2__3[[#This Row],[Customer ID]],Hospitalisation_Details_2__2!$1:$1048576,11,FALSE) -> tier - 2 | P26: =VLOOKUP(Hospitalisation_Details_2__3[[#This Row],[Customer ID]],Hospitalisation_Details_2__2!$1:$1048576,12,FALSE) -> R1013 | Q26: =VLOOKUP(Hospitalisation_Details_2__3[[#This Row],[Customer ID]],Hospitalisation_Details_2__2!$1:$1048576,13,FALSE) -> 25
A27: Id2310 | B27: =VLOOKUP(Customer_Names!A27,Customer_Names!$1:$1048576,4,FALSE) -> Adam | C27: =VLOOKUP(Medical_Examinations_2[[#This Row],[Customer ID]],Medical_Examinations!$1:$1048576,2,FALSE) -> 33.88 | D27: =VLOOKUP(Medical_Examinations_2[[#This Row],[Customer ID]],Medical_Examinations!$1:$1048576,4,FALSE) -> 7.01 | E27: =VLOOKUP(Medical_Examinations_2[[#This Row],[Customer ID]],Medical_Examinations!$1:$1048576,6,FALSE) -> No | F27: =VLOOKUP(Medical_Examinations_2[[#This Row],[Customer ID]],Medical_Examinations!$1:$1048576,7,FALSE) -> No | H27: =VLOOKUP(Medical_Examinations_2[[#This Row],[Customer ID]],Medical_Examinations!$1:$1048576,9,FALSE) -> 3 | I27: =VLOOKUP(Medical_Examinations_2[[#This Row],[Customer ID]],Medical_Examinations!$1:$1048576,11,FALSE) -> Yes | J27: =VLOOKUP(Medical_Examinations_2[[#This Row],[Customer ID]],Medical_Examinations!$1:$1048576,3,FALSE) -> Obesity | K27: =VLOOKUP(Medical_Examinations_2[[#This Row],[Customer ID]],Medical_Examinations!$1:$1048576,5,FALSE) -> Diabetes | L27: =VLOOKUP(Hospitalisation_Details_2__3[[#This Row],[Customer ID]],Hospitalisation_Details_2__2!$1:$1048576,7,FALSE) -> 34660 | M27: =VLOOKUP(Hospitalisation_Details_2__3[[#This Row],[Customer ID]],Hospitalisation_Details_2__2!$1:$1048576,9,FALSE) -> $1006.65 | N27: =VLOOKUP(Hospitalisation_Details_2__3[[#This Row],[Customer ID]],Hospitalisation_Details_2__2!$1:$1048576,10,FALSE) -> tier - 3 | O27: =VLOOKUP(Hospitalisation_Details_2__3[[#This Row],[Customer ID]],Hospitalisation_Details_2__2!$1:$1048576,11,FALSE) -> tier - 2 | P27: =VLOOKUP(Hospitalisation_Details_2__3[[#This Row],[Customer ID]],Hospitalisation_Details_2__2!$1:$1048576,12,FALSE) -> R1013 | Q27: =VLOOKUP(Hospitalisation_Details_2__3[[#This Row],[Customer ID]],Hospitalisation_Details_2__2!$1:$1048576,13,FALSE) -> 32
A28: Id2309 | B28: =VLOOKUP(Customer_Names!A28,Customer_Names!$1:$1048576,4,FALSE) -> Mr. Zach | C28: =VLOOKUP(Medical_Examinations_2[[#This Row],[Customer ID]],Medical_Examinations!$1:$1048576,2,FALSE) -> 30.875 | D28: =VLOOKUP(Medical_Examinations_2[[#This Row],[Customer ID]],Medical_Examinations!$1:$1048576,4,FALSE) -> 11.88 | E28: =VLOOKUP(Medical_Examinations_2[[#This Row],[Customer ID]],Medical_Examinations!$1:$1048576,6,FALSE) -> No | F28: =VLOOKUP(Medical_Examinations_2[[#This Row],[Customer ID]],Medical_Examinations!$1:$1048576,7,FALSE) -> No | H28: =VLOOKUP(Medical_Examinations_2[[#This Row],[Customer ID]],Medical_Examinations!$1:$1048576,9,FALSE) -> No major surgery | I28: =VLOOKUP(Medical_Examinations_2[[#This Row],[Customer ID]],Medical_Examinations!$1:$1048576,11,FALSE) -> Yes | J28: =VLOOKUP(Medical_Examinations_2[[#This Row],[Customer ID]],Medical_Examinations!$1:$1048576,3,FALSE) -> Obesity | K28: =VLOOKUP(Medical_Examinations_2[[#This Row],[Customer ID]],Medical_Examinations!$1:$1048576,5,FALSE) -> Diabetes | L28: =VLOOKUP(Hospitalisation_Details_2__3[[#This Row],[Customer ID]],Hospitalisation_Details_2__2!$1:$1048576,7,FALSE) -> 36808 | M28: =VLOOKUP(Hospitalisation_Details_2__3[[#This Row],[Customer ID]],Hospitalisation_Details_2__2!$1:$1048576,9,FALSE) -> $1012 | N28: =VLOOKUP(Hospitalisation_Details_2__3[[#This Row],[Customer ID]],Hospitalisation_Details_2__2!$1:$1048576,10,FALSE) -> tier - 3 | O28: =VLOOKUP(Hospitalisation_Details_2__3[[#This Row],[Customer ID]],Hospitalisation_Details_2__2!$1:$1048576,11,FALSE) -> tier - 2 | P28: =VLOOKUP(Hospitalisation_Details_2__3[[#This Row],[Customer ID]],Hospitalisation_Details_2__2!$1:$1048576,12,FALSE) -> R1013 | Q28: =VLOOKUP(Hospitalisation_Details_2__3[[#This Row],[Customer ID]],Hospitalisation_Details_2__2!$1:$1048576,13,FALSE) -> 26
A29: Id2308 | B29: =VLOOKUP(Customer_Names!A29,Customer_Names!$1:$1048576,4,FALSE) -> Stephanie W. | C29: =VLOOKUP(Medical_Examinations_2[[#This Row],[Customer ID]],Medical_Examinations!$1:$1048576,2,FALSE) -> 36.86 | D29: =VLOOKUP(Medical_Examinations_2[[#This Row],[Customer ID]],Medical_Examinations!$1:$1048576,4,FALSE) -> 5.19 | E29: =VLOOKUP(Medical_Examinations_2[[#This Row],[Customer ID]],Medical_Examinations!$1:$1048576,6,FALSE) -> Yes | F29: =VLOOKUP(Medical_Examinations_2[[#This Row],[Customer ID]],Medical_Examinations!$1:$1048576,7,FALSE) -> No | H29: =VLOOKUP(Medical_Examinations_2[[#This Row],[Customer ID]],Medical_Examinations!$1:$1048576,9,FALSE) -> 1 | I29: =VLOOKUP(Medical_Examinations_2[[#This Row],[Customer ID]],Medical_Examinations!$1:$1048576,11,FALSE) -> Yes | J29: =VLOOKUP(Medical_Examinations_2[[#This Row],[Customer ID]],Medical_Examinations!$1:$1048576,3,FALSE) -> Obesity | K29: =VLOOKUP(Medical_Examinations_2[[#This Row],[Customer ID]],Medical_Examinations!$1:$1048576,5,FALSE) -> Normal | L29: =VLOOKUP(Hospitalisation_Details_2__3[[#This Row],[Customer ID]],Hospitalisation_Details_2__2!$1:$1048576,7,FALSE) -> 36377 | M29: =VLOOKUP(Hospitalisation_Details_2__3[[#This Row],[Customer ID]],Hospitalisation_Details_2__2!$1:$1048576,9,FALSE) -> $1019 | N29: =VLOOKUP(Hospitalisation_Details_2__3[[#This Row],[Customer ID]],Hospitalisation_Details_2__2!$1:$1048576,10,FALSE) -> tier - 3 | O29: =VLOOKUP(Hospitalisation_Details_2__3[[#This Row],[Customer ID]],Hospitalisation_Details_2__2!$1:$1048576,11,FALSE) -> tier - 2 | P29: =VLOOKUP(Hospitalisation_Details_2__3[[#This Row],[Customer ID]],Hospitalisation_Details_2__2!$1:$1048576,12,FALSE) -> R1013 | Q29: =VLOOKUP(Hospitalisation_Details_2__3[[#This Row],[Customer ID]],Hospitalisation_Details_2__2!$1:$1048576,13,FALSE) -> 27
A30: Id2307 | B30: =VLOOKUP(Customer_Names!A30,Customer_Names!$1:$1048576,4,FALSE) -> Stephen | C30: =VLOOKUP(Medical_Examinations_2[[#This Row],[Customer ID]],Medical_Examinations!$1:$1048576,2,FALSE) -> 35.86 | D30: =VLOOKUP(Medical_Examinations_2[[#This Row],[Customer ID]],Medical_Examinations!$1:$1048576,4,FALSE) -> 6.74 | E30: =VLOOKUP(Medical_Examinations_2[[#This Row],[Customer ID]],Medical_Examinations!$1:$1048576,6,FALSE) -> Yes | F30: =VLOOKUP(Medical_Examinations_2[[#This Row],[Customer ID]],Medical_Examinations!$1:$1048576,7,FALSE) -> No | H30: =VLOOKUP(Medical_Examinations_2[[#This Row],[Customer ID]],Medical_Examinations!$1:$1048576,9,FALSE) -> 2 | I30: =VLOOKUP(Medical_Examinations_2[[#This Row],[Customer ID]],Medical_Examinations!$1:$1048576,11,FALSE) -> Yes | J30: =VLOOKUP(Medical_Examinations_2[[#This Row],[Customer ID]],Medical_Examinations!$1:$1048576,3,FALSE) -> Obesity | K30: =VLOOKUP(Medical_Examinations_2[[#This Row],[Customer ID]],Medical_Examinations!$1:$1048576,5,FALSE) -> Diabetes | L30: =VLOOKUP(Hospitalisation_Details_2__3[[#This Row],[Customer ID]],Hospitalisation_Details_2__2!$1:$1048576,7,FALSE) -> 34977 | M30: =VLOOKUP(Hospitalisation_Details_2__3[[#This Row],[Customer ID]],Hospitalisation_Details_2__2!$1:$1048576,9,FALSE) -> $1033.74 | N30: =VLOOKUP(Hospitalisation_Details_2__3[[#This Row],[Customer ID]],Hospitalisation_Details_2__2!$1:$1048576,10,FALSE) -> tier - 3 | O30: =VLOOKUP(Hospitalisation_Details_2__3[[#This Row],[Customer ID]],Hospitalisation_Details_2__2!$1:$1048576,11,FALSE) -> tier - 1 | P30: =VLOOKUP(Hospitalisation_Details_2__3[[#This Row],[Customer ID]],Hospitalisation_Details_2__2!$1:$1048576,12,FALSE) -> R1013 | Q30: =VLOOKUP(Hospitalisation_Details_2__3[[#This Row],[Customer ID]],Hospitalisation_Details_2__2!$1:$1048576,13,FALSE) -> 31
A31: Id2306 | B31: =VLOOKUP(Customer_Names!A31,Customer_Names!$1:$1048576,4,FALSE) -> Natalie | C31: =VLOOKUP(Medical_Examinations_2[[#This Row],[Customer ID]],Medical_Examinations!$1:$1048576,2,FALSE) -> 37.05 | D31: =VLOOKUP(Medical_Examinations_2[[#This Row],[Customer ID]],Medical_Examinations!$1:$1048576,4,FALSE) -> 8.44 | E31: =VLOOKUP(Medical_Examinations_2[[#This Row],[Customer ID]],Medical_Examinations!$1:$1048576,6,FALSE) -> No | F31: =VLOOKUP(Medical_Examinations_2[[#This Row],[Customer ID]],Medical_Examinations!$1:$1048576,7,FALSE) -> No | H31: =VLOOKUP(Medical_Examinations_2[[#This Row],[Customer ID]],Medical_Examinations!$1:$1048576,9,FALSE) -> No major surgery | I31: =VLOOKUP(Medical_Examinations_2[[#This Row],[Customer ID]],Medical_Examinations!$1:$1048576,11,FALSE) -> Yes | J31: =VLOOKUP(Medical_Examinations_2[[#This Row],[Customer ID]],Medical_Examinations!$1:$1048576,3,FALSE) -> Obesity | K31: =VLOOKUP(Medical_Examinations_2[[#This Row],[Customer ID]],Medical_Examinations!$1:$1048576,5,FALSE) -> Diabetes | L31: =VLOOKUP(Hospitalisation_Details_2__3[[#This Row],[Customer ID]],Hospitalisation_Details_2__2!$1:$1048576,7,FALSE) -> 34655 | M31: =VLOOKUP(Hospitalisation_Details_2__3[[#This Row],[Customer ID]],Hospitalisation_Details_2__2!$1:$1048576,9,FALSE) -> $1044 | N31: =VLOOKUP(Hospitalisation_Details_2__3[[#This Row],[Customer ID]],Hospitalisation_Details_2__2!$1:$1048576,10,FALSE) -> tier - 3 | O31: =VLOOKUP(Hospitalisation_Details_2__3[[#This Row],[Customer ID]],Hospitalisation_Details_2__2!$1:$1048576,11,FALSE) -> tier - 2 | P31: =VLOOKUP(Hospitalisation_Details_2__3[[#This Row],[Customer ID]],Hospitalisation_Details_2__2!$1:$1048576,12,FALSE) -> R1013 | Q31: =VLOOKUP(Hospitalisation_Details_2__3[[#This Row],[Customer ID]],Hospitalisation_Details_2__2!$1:$1048576,13,FALSE) -> 32
